[2021-10-24 13:36:57,227] [utils.custom_logger] [ERROR]: [BASE PLAYWRIGHT] : Either proxy or connection refused error - NS_ERROR_PROXY_FORBIDDEN
=========================== logs ===========================
navigating to "https://browserleaks.com/ip", waiting until "load"
============================================================ 
	[base.py:26)]

[2021-10-24 13:36:57,665] [utils.custom_logger] [ERROR]: [BASE PLAYWRIGHT] : Either proxy or connection refused error - NS_ERROR_PROXY_FORBIDDEN
=========================== logs ===========================
navigating to "https://browserleaks.com/ip", waiting until "load"
============================================================ 
	[base.py:26)]

[2021-10-24 16:05:52,473] [utils.custom_logger] [ERROR]: [Task 0] : Webhook Failed 
	[base.py:35)]
Traceback (most recent call last):
  File "C:\Users\lafft\PycharmProjects\FTLAEMonitor\utils\webhook.py", line 32, in send_webhook
    await webhook.send(username='FTL.AE Monitor',
  File "C:\Users\lafft\AppData\Roaming\Python\Python39\site-packages\discord\webhook.py", line 266, in handle_execution_response
    data = await response
  File "C:\Users\lafft\AppData\Roaming\Python\Python39\site-packages\discord\webhook.py", line 221, in request
    async with self.session.request(verb, url, headers=headers, data=data) as r:
AttributeError: __aenter__
[2021-10-24 16:05:52,474] [utils.custom_logger] [ERROR]: [Task 0] : Webhook Failed 
	[base.py:35)]
Traceback (most recent call last):
  File "C:\Users\lafft\PycharmProjects\FTLAEMonitor\utils\webhook.py", line 32, in send_webhook
    await webhook.send(username='FTL.AE Monitor',
  File "C:\Users\lafft\AppData\Roaming\Python\Python39\site-packages\discord\webhook.py", line 266, in handle_execution_response
    data = await response
  File "C:\Users\lafft\AppData\Roaming\Python\Python39\site-packages\discord\webhook.py", line 221, in request
    async with self.session.request(verb, url, headers=headers, data=data) as r:
AttributeError: __aenter__
[2021-10-24 16:05:54,482] [utils.custom_logger] [ERROR]: [Task 0] : Webhook Failed 
	[base.py:35)]
Traceback (most recent call last):
  File "C:\Users\lafft\PycharmProjects\FTLAEMonitor\utils\webhook.py", line 32, in send_webhook
    await webhook.send(username='FTL.AE Monitor',
  File "C:\Users\lafft\AppData\Roaming\Python\Python39\site-packages\discord\webhook.py", line 266, in handle_execution_response
    data = await response
  File "C:\Users\lafft\AppData\Roaming\Python\Python39\site-packages\discord\webhook.py", line 221, in request
    async with self.session.request(verb, url, headers=headers, data=data) as r:
AttributeError: __aenter__
[2021-10-24 16:05:54,487] [utils.custom_logger] [ERROR]: [Task 0] : Webhook Failed 
	[base.py:35)]
Traceback (most recent call last):
  File "C:\Users\lafft\PycharmProjects\FTLAEMonitor\utils\webhook.py", line 32, in send_webhook
    await webhook.send(username='FTL.AE Monitor',
  File "C:\Users\lafft\AppData\Roaming\Python\Python39\site-packages\discord\webhook.py", line 266, in handle_execution_response
    data = await response
  File "C:\Users\lafft\AppData\Roaming\Python\Python39\site-packages\discord\webhook.py", line 221, in request
    async with self.session.request(verb, url, headers=headers, data=data) as r:
AttributeError: __aenter__
[2021-10-27 17:01:18,254] [utils.custom_logger] [ERROR]: Webhook Failed 
	[webhook.py:51)]
Traceback (most recent call last):
  File "C:\Users\lafft\PycharmProjects\FTLAEMonitor\utils\webhook.py", line 42, in send_webhook
    await webhook.send(username='FTL.AE Monitor',
  File "C:\Users\lafft\AppData\Roaming\Python\Python39\site-packages\discord\webhook.py", line 266, in handle_execution_response
    data = await response
  File "C:\Users\lafft\AppData\Roaming\Python\Python39\site-packages\discord\webhook.py", line 242, in request
    raise HTTPException(r, data)
discord.errors.HTTPException: 429 Too Many Requests (error code: 0): {"embeds":[{"footer":{"text":"WINX4 Bots - winwinwinwin#0001","icon_url":"https://images6.alphacoders.com/909/thumb-1920-909641.png"},"thumbnail":{"url":"https://www.footlocker.ae/sites/g/files/bndsjb891/files/styles/product_listing/public/media/als-ecom-pimsfl-prod-s3/assets/FootLocker/314215317604_02.1523082.jpg?itok=NfawwqGM"},"fields":[{"inline":false,"name":"Status","value":"Product Live!"},{"inline":false,"name":"Price","value":"659"},{"inline":false,"name":"Stock","value":"15"},{"inline":false,"name":"SKU","value":"LF314215317604"}],"color":3066993,"type":"rich","url":"https://www.footlocker.ae/en/buy-new-balance-5740-mens-shoes-white-0.html","title":"New Balance 5740 - Men's Shoes"}],"tts":false,"avatar_url":"https://d1yjjnpx0p53s8.cloudfront.net/styles/logo-thumbnail/s3/0002/5414/brand.gif?itok=c0LjV97s","username":"FTL.AE Monitor"}
[2021-10-27 17:01:18,308] [utils.custom_logger] [ERROR]: Webhook Failed 
	[webhook.py:51)]
Traceback (most recent call last):
  File "C:\Users\lafft\PycharmProjects\FTLAEMonitor\utils\webhook.py", line 42, in send_webhook
    await webhook.send(username='FTL.AE Monitor',
  File "C:\Users\lafft\AppData\Roaming\Python\Python39\site-packages\discord\webhook.py", line 266, in handle_execution_response
    data = await response
  File "C:\Users\lafft\AppData\Roaming\Python\Python39\site-packages\discord\webhook.py", line 242, in request
    raise HTTPException(r, data)
discord.errors.HTTPException: 429 Too Many Requests (error code: 0): {"embeds":[{"footer":{"text":"WINX4 Bots - winwinwinwin#0001","icon_url":"https://images6.alphacoders.com/909/thumb-1920-909641.png"},"thumbnail":{"url":"https://www.footlocker.ae/sites/g/files/bndsjb891/files/styles/product_listing/public/media/als-ecom-pimsfl-prod-s3/assets/FootLocker/314215317604_02.1523082.jpg?itok=NfawwqGM"},"fields":[{"inline":false,"name":"Status","value":"Product Live!"},{"inline":false,"name":"Price","value":"659"},{"inline":false,"name":"Stock","value":"15"},{"inline":false,"name":"SKU","value":"LF314215317604"}],"color":3066993,"type":"rich","url":"https://www.footlocker.ae/en/buy-new-balance-5740-mens-shoes-white-0.html","title":"New Balance 5740 - Men's Shoes"}],"tts":false,"avatar_url":"https://d1yjjnpx0p53s8.cloudfront.net/styles/logo-thumbnail/s3/0002/5414/brand.gif?itok=c0LjV97s","username":"FTL.AE Monitor"}
[2021-10-27 17:01:18,347] [utils.custom_logger] [ERROR]: Webhook Failed 
	[webhook.py:51)]
Traceback (most recent call last):
  File "C:\Users\lafft\PycharmProjects\FTLAEMonitor\utils\webhook.py", line 42, in send_webhook
    await webhook.send(username='FTL.AE Monitor',
  File "C:\Users\lafft\AppData\Roaming\Python\Python39\site-packages\discord\webhook.py", line 266, in handle_execution_response
    data = await response
  File "C:\Users\lafft\AppData\Roaming\Python\Python39\site-packages\discord\webhook.py", line 242, in request
    raise HTTPException(r, data)
discord.errors.HTTPException: 429 Too Many Requests (error code: 0): {"embeds":[{"footer":{"text":"WINX4 Bots - winwinwinwin#0001","icon_url":"https://images6.alphacoders.com/909/thumb-1920-909641.png"},"thumbnail":{"url":"https://www.footlocker.ae/sites/g/files/bndsjb891/files/styles/product_listing/public/media/als-ecom-pimsfl-prod-s3/assets/FootLocker/314215317604_02.1523082.jpg?itok=NfawwqGM"},"fields":[{"inline":false,"name":"Status","value":"Product Live!"},{"inline":false,"name":"Price","value":"659"},{"inline":false,"name":"Stock","value":"15"},{"inline":false,"name":"SKU","value":"LF314215317604"}],"color":3066993,"type":"rich","url":"https://www.footlocker.ae/en/buy-new-balance-5740-mens-shoes-white-0.html","title":"New Balance 5740 - Men's Shoes"}],"tts":false,"avatar_url":"https://d1yjjnpx0p53s8.cloudfront.net/styles/logo-thumbnail/s3/0002/5414/brand.gif?itok=c0LjV97s","username":"FTL.AE Monitor"}
[2021-10-27 17:02:33,700] [utils.custom_logger] [ERROR]: WTF Happened? 
	[backend_monitor.py:205)]
Traceback (most recent call last):
  File "C:\Program Files\Python39\lib\asyncio\runners.py", line 44, in run
    return loop.run_until_complete(main)
  File "C:\Program Files\Python39\lib\asyncio\base_events.py", line 629, in run_until_complete
    self.run_forever()
  File "C:\Program Files\Python39\lib\asyncio\windows_events.py", line 316, in run_forever
    super().run_forever()
  File "C:\Program Files\Python39\lib\asyncio\base_events.py", line 596, in run_forever
    self._run_once()
  File "C:\Program Files\Python39\lib\asyncio\base_events.py", line 1854, in _run_once
    event_list = self._selector.select(timeout)
  File "C:\Program Files\Python39\lib\asyncio\windows_events.py", line 434, in select
    self._poll(timeout)
  File "C:\Program Files\Python39\lib\asyncio\windows_events.py", line 783, in _poll
    status = _overlapped.GetQueuedCompletionStatus(self._iocp, ms)
KeyboardInterrupt

During handling of the above exception, another exception occurred:

Traceback (most recent call last):
  File "C:\Users\lafft\PycharmProjects\FTLAEMonitor\backend_monitor.py", line 203, in run
    await asyncio.gather(check_auth(), check_forever())
asyncio.exceptions.CancelledError
[2021-10-28 03:47:50,636] [utils.custom_logger] [ERROR]: WTF Happened? 
	[backend_monitor.py:212)]
Traceback (most recent call last):
  File "C:\Program Files\Python39\lib\asyncio\runners.py", line 44, in run
    return loop.run_until_complete(main)
  File "C:\Program Files\Python39\lib\asyncio\base_events.py", line 629, in run_until_complete
    self.run_forever()
  File "C:\Program Files\Python39\lib\asyncio\windows_events.py", line 316, in run_forever
    super().run_forever()
  File "C:\Program Files\Python39\lib\asyncio\base_events.py", line 596, in run_forever
    self._run_once()
  File "C:\Program Files\Python39\lib\asyncio\base_events.py", line 1854, in _run_once
    event_list = self._selector.select(timeout)
  File "C:\Program Files\Python39\lib\asyncio\windows_events.py", line 434, in select
    self._poll(timeout)
  File "C:\Program Files\Python39\lib\asyncio\windows_events.py", line 783, in _poll
    status = _overlapped.GetQueuedCompletionStatus(self._iocp, ms)
KeyboardInterrupt

During handling of the above exception, another exception occurred:

Traceback (most recent call last):
  File "C:\Users\lafft\PycharmProjects\FTLAEMonitor\backend_monitor.py", line 210, in run
    await asyncio.gather(check_auth(), check_forever())
asyncio.exceptions.CancelledError
[2021-10-28 04:20:33,423] [utils.custom_logger] [ERROR]: Please contact @winwinwinwin#0001 on discord. 
	[backend_monitor.py:205)]
Traceback (most recent call last):
  File "C:\Program Files\Python39\lib\asyncio\runners.py", line 44, in run
    return loop.run_until_complete(main)
  File "C:\Program Files\Python39\lib\asyncio\base_events.py", line 629, in run_until_complete
    self.run_forever()
  File "C:\Program Files\Python39\lib\asyncio\windows_events.py", line 316, in run_forever
    super().run_forever()
  File "C:\Program Files\Python39\lib\asyncio\base_events.py", line 596, in run_forever
    self._run_once()
  File "C:\Program Files\Python39\lib\asyncio\base_events.py", line 1854, in _run_once
    event_list = self._selector.select(timeout)
  File "C:\Program Files\Python39\lib\asyncio\windows_events.py", line 434, in select
    self._poll(timeout)
  File "C:\Program Files\Python39\lib\asyncio\windows_events.py", line 783, in _poll
    status = _overlapped.GetQueuedCompletionStatus(self._iocp, ms)
KeyboardInterrupt

During handling of the above exception, another exception occurred:

Traceback (most recent call last):
  File "C:\Users\lafft\PycharmProjects\FTLAEMonitor\backend_monitor.py", line 203, in run
    await asyncio.gather(check_auth(), check_forever())
asyncio.exceptions.CancelledError
[2021-10-28 12:44:30,457] [utils.custom_logger] [ERROR]: Please contact @winwinwinwin#0001 on discord. 
	[backend_monitor.py:213)]
Traceback (most recent call last):
  File "C:\Program Files\Python39\lib\asyncio\runners.py", line 44, in run
    return loop.run_until_complete(main)
  File "C:\Program Files\Python39\lib\asyncio\base_events.py", line 629, in run_until_complete
    self.run_forever()
  File "C:\Program Files\Python39\lib\asyncio\windows_events.py", line 316, in run_forever
    super().run_forever()
  File "C:\Program Files\Python39\lib\asyncio\base_events.py", line 596, in run_forever
    self._run_once()
  File "C:\Program Files\Python39\lib\asyncio\base_events.py", line 1854, in _run_once
    event_list = self._selector.select(timeout)
  File "C:\Program Files\Python39\lib\asyncio\windows_events.py", line 434, in select
    self._poll(timeout)
  File "C:\Program Files\Python39\lib\asyncio\windows_events.py", line 783, in _poll
    status = _overlapped.GetQueuedCompletionStatus(self._iocp, ms)
KeyboardInterrupt

During handling of the above exception, another exception occurred:

Traceback (most recent call last):
  File "C:\Users\lafft\PycharmProjects\FTLAEMonitor\backend_monitor.py", line 211, in run
    await asyncio.gather(check_auth(), check_forever())
asyncio.exceptions.CancelledError
